<robot name="arm_description">
	<link name="Base_Link">
		<inertial>
			<origin xyz="0.0003064 0.0064691 0.00036833" rpy="0 0 0" />
			<mass value="0.51132" />
			<inertia ixx="0" ixy="0" ixz="0" iyy="0" iyz="0" izz="0" />
		</inertial>
		<visual>
			<origin xyz="0 0 0" rpy="0 0 0" />
			<geometry>
				<mesh filename="package://arm_description/meshes/Base_Link.STL" />
			</geometry>
			<material name="">
				<color rgba="0.79216 0.81961 0.93333 1" />
			</material>
		</visual>
		<collision>
			<origin xyz="0 0 0" rpy="0 0 0" />
			<geometry>
				<mesh filename="package://arm_description/meshes/Base_Link.STL" />
			</geometry>
		</collision>
	</link>
	<link name="Link_00">
		<inertial>
			<origin xyz="2.9296E-05 0.057647 0.0080497" rpy="0 0 0" />
			<mass value="0.91073" />
			<inertia ixx="0" ixy="0" ixz="0" iyy="0" iyz="0" izz="0" />
		</inertial>
		<visual>
			<origin xyz="0 0 0" rpy="0 0 0" />
			<geometry>
				<mesh filename="package://arm_description/meshes/Link_00.STL" />
			</geometry>
			<material name="">
				<color rgba="0.79216 0.81961 0.93333 1" />
			</material>
		</visual>
		<collision>
			<origin xyz="0 0 0" rpy="0 0 0" />
			<geometry>
				<mesh filename="package://arm_description/meshes/Link_00.STL" />
			</geometry>
		</collision>
	</link>
	<joint name="Base_to_00" type="continuous">
		<origin xyz="0 0 0.035" rpy="1.5708 -6.3309E-17 -1.5878" />
		<parent link="Base_Link" />
		<child link="Link_00" />
		<axis xyz="0 1 0" />
	</joint>
	<link name="Link_01">
		<inertial>
			<origin xyz="0.051312 0.09726 -1.3797E-05" rpy="0 0 0" />
			<mass value="1.5841" />
			<inertia ixx="0" ixy="0" ixz="0" iyy="0" iyz="0" izz="0" />
		</inertial>
		<visual>
			<origin xyz="0 0 0" rpy="0 0 0" />
			<geometry>
				<mesh filename="package://arm_description/meshes/Link_01.STL" />
			</geometry>
			<material name="">
				<color rgba="0.79216 0.81961 0.93333 1" />
			</material>
		</visual>
		<collision>
			<origin xyz="0 0 0" rpy="0 0 0" />
			<geometry>
				<mesh filename="package://arm_description/meshes/Link_01.STL" />
			</geometry>
		</collision>
	</link>
	<joint name="00_to_01" type="continuous">
		<origin xyz="0 0.07 0.078535" rpy="3.1384 -1.5708 0" />
		<parent link="Link_00" />
		<child link="Link_01" />
		<axis xyz="1 0 0" />
	</joint>
</robot>