<robot name="arm_model">
	<link name="world">
	</link>
	<link name="base_link">
		<inertial>
			<origin xyz="0.0003064 0.0064691 0.00036833" rpy="0 0 0" />
			<mass value="0.511320" />
			<inertia ixx="0.0005462" ixy="-0.0000031" ixz="0.0000000" iyy="0.0007163" iyz="-0.0000022" izz="0.0005442" />
		</inertial>
		<visual>
			<origin xyz="0 0 0" rpy="0 0 0" />
			<geometry>
				<mesh filename="package://arm_description/meshes/base_link.STL" />
			</geometry>
			<material name="">
				<color rgba="0.79216 0.81961 0.93333 1" />
			</material>
		</visual>
		<collision>
			<origin xyz="0 0 0" rpy="0 0 0" />
			<geometry>
				<mesh filename="package://arm_description/meshes/base_link.STL" />
			</geometry>
		</collision>
	</link>
	<joint name="world_joint" type="fixed">
		<parent link="world" />
		<child link="base_link" />
	</joint>
	<link name="link_00">
		<inertial>
			<origin xyz="2.9298E-05 0.057647 0.0080497" rpy="0 0 0" />
			<mass value="0.91073" />
			<inertia ixx="0.0089782" ixy="-0.0007696" ixz="-0.0000172" iyy="0.0016978" iyz="0.0000156" izz="0.0098854" />
		</inertial>
		<visual>
			<origin xyz="0 0 0" rpy="0 0 0" />
			<geometry>
				<mesh filename="package://arm_description/meshes/link_00.STL" />
			</geometry>
			<material name="">
				<color rgba="0.79216 0.81961 0.93333 1" />
			</material>
		</visual>
		<collision>
			<origin xyz="0 0 0" rpy="0 0 0" />
			<geometry>
				<mesh filename="package://arm_description/meshes/link_00.STL" />
			</geometry>
		</collision>
	</link>
	<joint name="base_to_00" type="continuous">
		<origin xyz="0 0 0.035" rpy="1.5708 -6.1219E-17 -1.5519" />
		<parent link="base_link" />
		<child link="link_00" />
		<axis xyz="0 1 0" />
		<limit effort="10" velocity="10" />
	</joint>
	<link name="link_01">
		<inertial>
			<origin xyz="0.049553 0.060376 -2.116E-05" rpy="0 0 0" />
			<mass value="1.0247" />
			<inertia ixx="0.0299083" ixy="-0.0203557" ixz="0.0047231" iyy="0.0213327" iyz="-0.0075678" izz="0.0447374" />
		</inertial>
		<visual>
			<origin xyz="0 0 0" rpy="0 0 0" />
			<geometry>
				<mesh filename="package://arm_description/meshes/link_01.STL" />
			</geometry>
			<material name="">
				<color rgba="0.79216 0.81961 0.93333 1" />
			</material>
		</visual>
		<collision>
			<origin xyz="0 0 0" rpy="0 0 0" />
			<geometry>
				<mesh filename="package://arm_description/meshes/link_01.STL" />
			</geometry>
		</collision>
	</link>
	<joint name="00_to_01" type="revolute">
		<origin xyz="0 0.07 0.080036" rpy="2.4677 -1.5708 0" />
		<parent link="link_00" />
		<child link="link_01" />
		<axis xyz="-1 0 0" />
		<limit lower="2" upper="3" effort="10" velocity="10" />
	</joint>
	<link name="link_02">
		<inertial>
			<origin xyz="0.049675 0.04972 3.3596E-05" rpy="0 0 0" />
			<mass value="0.49537" />
			<inertia ixx="0.0370922" ixy="-0.0040054" ixz="0.0009423" iyy="0.0035271" iyz="-0.0065162" izz="0.0350452" />
		</inertial>
		<visual>
			<origin xyz="0 0 0" rpy="0 0 0" />
			<geometry>
				<mesh filename="package://arm_description/meshes/link_02.STL" />
			</geometry>
			<material name="">
				<color rgba="0.79216 0.81961 0.93333 1" />
			</material>
		</visual>
		<collision>
			<origin xyz="0 0 0" rpy="0 0 0" />
			<geometry>
				<mesh filename="package://arm_description/meshes/link_02.STL" />
			</geometry>
		</collision>
	</link>
	<joint name="01_to_02" type="revolute">
		<origin xyz="0 0.15 0" rpy="-1.7159 -9.3328E-16 3.1416" />
		<parent link="link_01" />
		<child link="link_02" />
		<axis xyz="1 0 0" />
		<limit lower="2" upper="3" effort="10" velocity="10" />
	</joint>

	<!-- ros_control plugin -->
	<gazebo>
		<plugin name="gazebo_ros_control" filename="libgazebo_ros_control.so">
			<robotNamespace>/arm_model</robotNamespace>
		</plugin>
	</gazebo>

	<!-- Transmissions for ROS Control -->
	<transmission name="tran1">
		<type>transmission_interface/SimpleTransmission</type>
		<joint name="base_to_00">
			<hardwareInterface>EffortJointInterface</hardwareInterface>
		</joint>
		<actuator name="motor1">
			<hardwareInterface>EffortJointInterface</hardwareInterface>
			<mechanicalReduction>1</mechanicalReduction>
		</actuator>
	</transmission>

	<transmission name="tran2">
		<type>transmission_interface/SimpleTransmission</type>
		<joint name="00_to_01">
			<hardwareInterface>EffortJointInterface</hardwareInterface>
		</joint>
		<actuator name="motor2">
			<hardwareInterface>EffortJointInterface</hardwareInterface>
			<mechanicalReduction>1</mechanicalReduction>
		</actuator>
	</transmission>

	<transmission name="tran3">
		<type>transmission_interface/SimpleTransmission</type>
		<joint name="01_to_02">
			<hardwareInterface>EffortJointInterface</hardwareInterface>
		</joint>
		<actuator name="motor3">
			<hardwareInterface>EffortJointInterface</hardwareInterface>
			<mechanicalReduction>1</mechanicalReduction>
		</actuator>
	</transmission>
</robot>