<?xml version="1.0"?>
<robot name="arm_robot">
	<link name="world">
	</link>
	<link name="Base_Link">
		<inertial>
			<origin xyz="4.9361E-21 -0.18689 -0.0014716" rpy="0 0 0" />
			<mass value="566.27" />
			<inertia ixx="121.33" ixy="0" ixz="0" iyy="89.866" iyz="0.083333" izz="121" />
		</inertial>
		<visual>
			<origin xyz="0 0 0" rpy="0 0 0" />
			<geometry>
				<mesh filename="package://robot_description/meshes/Base_Link.STL" />
			</geometry>
			<material name="">
				<color rgba="0.79216 0.81961 0.93333 1" />
			</material>
		</visual>
		<collision>
			<origin xyz="0 0 0" rpy="0 0 0" />
			<geometry>
				<mesh filename="package://robot_description/meshes/Base_Link.STL" />
			</geometry>
		</collision>
	</link>
	<joint name="world_joint" type="fixed">
		<origin xyz="0.0 0.0 0.0" rpy="0.0 0.0 0.0"/>
		<parent link="world"/>
		<child link="Base_Link"/>
	</joint>
	<link name="Link_01">
		<inertial>
			<origin xyz="6.3251E-08 0.40154 -9.1156E-08" rpy="0 0 0" />
			<mass value="264.92" />
			<inertia ixx="203.49" ixy="-2.9E-05" ixz="-0.85143" iyy="24.578" iyz="-3.2E-05" izz="194.3" />
		</inertial>
		<visual>
			<origin xyz="0 0 0" rpy="0 0 0" />
			<geometry>
				<mesh filename="package://robot_description/meshes/Link_01.STL" />
			</geometry>
			<material name="">
				<color rgba="0.79216 0.81961 0.93333 1" />
			</material>
		</visual>
		<collision>
			<origin xyz="0 0 0" rpy="0 0 0" />
			<geometry>
				<mesh filename="package://robot_description/meshes/Link_01.STL" />
			</geometry>
		</collision>
	</link>
	<joint name="Base_Link_to_Link_01" type="continuous">
		<origin xyz="0 0 0.4" rpy="1.5708 6.0973E-17 1.4792" />
		<parent link="Base_Link" />
		<child link="Link_01" />
		<axis xyz="0 1 0" />
	</joint>
	<link name="Link_02">
		<inertial>
			<origin xyz="-4.1633E-17 0.53964 1.4433E-15" rpy="0 0 0" />
			<mass value="75.925" />
			<inertia ixx="147.12" ixy="-50.573" ixz="2.0856" iyy="23.993" iyz="-4.6477" izz="169.62" />
		</inertial>
		<visual>
			<origin xyz="0 0 0" rpy="0 0 0" />
			<geometry>
				<mesh filename="package://robot_description/meshes/Link_02.STL" />
			</geometry>
			<material name="">
				<color rgba="0.79216 0.81961 0.93333 1" />
			</material>
		</visual>
		<collision>
			<origin xyz="0 0 0" rpy="0 0 0" />
			<geometry>
				<mesh filename="package://robot_description/meshes/Link_02.STL" />
			</geometry>
		</collision>
	</link>
	<joint name="Link_01_to_Link_02" type="continuous">
		<origin xyz="0 0.585 0" rpy="-2.3012 2.4425E-15 3.1416" />
		<parent link="Link_01" />
		<child link="Link_02" />
		<axis xyz="1 0 0" />
	</joint>
	<link name="Link_03">
		<inertial>
			<origin xyz="1.5032E-08 0.29365 -5.7063E-08" rpy="0 0 0" />
			<mass value="21.675" />
			<inertia ixx="99.474" ixy="-43.65" ixz="1.7658" iyy="19.859" iyz="-4.0115" izz="118.52" />
		</inertial>
		<visual>
			<origin xyz="0 0 0" rpy="0 0 0" />
			<geometry>
				<mesh filename="package://robot_description/meshes/Link_03.STL" />
			</geometry>
			<material name="">
				<color rgba="0.79216 0.81961 0.93333 1" />
			</material>
		</visual>
		<collision>
			<origin xyz="0 0 0" rpy="0 0 0" />
			<geometry>
				<mesh filename="package://robot_description/meshes/Link_03.STL" />
			</geometry>
		</collision>
	</link>
	<joint name="Link_02_to_Link_03" type="continuous">
		<origin xyz="0 1.275 0" rpy="-0.84042 9.09E-16 -1.0131E-15" />
		<parent link="Link_02" />
		<child link="Link_03" />
		<axis xyz="1 0 0" />
	</joint>
</robot>