<?xml version="1.0"?>
<robot name="robot_description">
	<link name="base_link">
		<inertial>
			<origin xyz="2.9297E-05 0.047647 0.0080497" rpy="0 0 0" />
			<mass value="0.91073" />
			<inertia ixx="0" ixy="0" ixz="0" iyy="0" iyz="0" izz="0" />
		</inertial>
		<visual>
			<origin xyz="0 0 0" rpy="0 0 0" />
			<geometry>
				<mesh filename="package://robot_description/meshes/base_link.STL" />
			</geometry>
			<material name="">
				<color rgba="0.79216 0.81961 0.93333 1" />
			</material>
		</visual>
		<collision>
			<origin xyz="0 0 0" rpy="0 0 0" />
			<geometry>
				<mesh filename="package://robot_description/meshes/base_link.STL" />
			</geometry>
		</collision>
	</link>
	<link name="link_01">
		<inertial>
			<origin xyz="0.049847 0.0010437 -0.097255" rpy="0 0 0" />
			<mass value="1.5841" />
			<inertia ixx="0" ixy="0" ixz="0" iyy="0" iyz="0" izz="0" />
		</inertial>
		<visual>
			<origin xyz="0 0 0" rpy="0 0 0" />
			<geometry>
				<mesh filename="package://robot_description/meshes/link_01.STL" />
			</geometry>
			<material name="">
				<color rgba="0.79216 0.81961 0.93333 1" />
			</material>
		</visual>
		<collision>
			<origin xyz="0 0 0" rpy="0 0 0" />
			<geometry>
				<mesh filename="package://robot_description/meshes/link_01.STL" />
			</geometry>
		</collision>
	</link>
	<joint name="joint_01" type="continuous">
		<origin xyz="0 -0.08 0.06" rpy="-2.3616 -3.0617E-17 -1.5708" />
		<parent link="base_link" />
		<child link="link_01" />
		<axis xyz="1 0 0" />
	</joint>
</robot>